Workbook

Sheet Strategy Parameters
A1: ⚙ STRATEGY PARAMETERS & ASSUMPTIONS
A2: FILTER RULES
A3: Trend Filter | B3: Price > 50 EMA > 200 EMA > 0 | C3: All three must hold simultaneously
A4: 52W High Proximity | B4: Price ≥ 52W High × 0.85 | C4: Within 15% of 52-week high
A5: 3M Breakout | B5: Price ≥ 3M High (65-day) | C5: Price making a new 65-day high
A6: Volume Surge | B6: 1M Median Vol > 3M Median Vol | C6: Rising accumulation confirmation
A8: RANKING WEIGHTS
A9: 3M Momentum | B9: 30% | C9: Percentile rank of 3-month return
A10: Volume Surge Ratio | B10: 25% | C10: Percentile rank of 1M/3M volume ratio
A11: Breakout Strength | B11: 25% | C11: Percentile rank of (Price−3M High)/3M High
A12: EMA Separation | B12: 20% | C12: Percentile rank of (Price−50EMA)/50EMA
A14: TRADE MANAGEMENT
A15: Universe | B15: Nifty 750 | C15: NSE listed Nifty 750 stocks
A16: Entry Day & Time | B16: Every Monday at 3:00 PM | C16: Market order near close
A17: Max Positions | B17: 20 | C17: Equal weight allocation
A18: Position Size | B18: Portfolio ÷ 20 | C18: Equal weight per trade
A19: Trailing Stop Loss | B19: Entry Price × 0.95 | C19: 5% TSL from entry
A20: Profit Target | B20: Entry Price × 1.10 | C20: 10% target per trade
A21: Max Holding Period | B21: 1 Calendar Month | C21: Exit regardless on month-end
A22: Re-entry | B22: Allowed next Monday | C22: If stock re-qualifies after stop-out

Sheet Ticker Data
A1: 📊 NIFTY 750 MOMENTUM SCREENER — Ticker Data Input
A2: Enter OHLCV and indicator data below. Blue cells = manual inputs. Screener tab auto-calculates signals and ranking.
A3: Ticker | B3: Company Name | C3: Current Price | D3: 50 EMA | E3: 200 EMA | F3: 52W High | G3: 3M High (65-day) | H3: 3M Low (65-day) | I3: 1M Median Volume | J3: 3M Median Volume | K3: 3M Return % | L3: Sector
A4: PRSMJOHNSN | B4: Reliance Industries | C4: 133.23 | D4: 126.72 | E4: 134.15 | F4: 176 | G4: 143.44 | H4: 118.65 | I4: 180813 | J4: 254506 | K4: 3.36 | L4: Energy
A5: CASTROLIND | B5: Infosys | C5: 183.34 | D5: 180.49 | E5: 187.27 | F5: 222.2 | G5: 184.77 | H5: 173.52 | I5: 1705913 | J5: 1594944 | K5: 0.56 | L5: IT
A6: ZYDUSLIFE | B6: HDFC Bank | C6: 929.9 | D6: 906.87 | E6: 921.92 | F6: 1059.05 | G6: 949.1 | H6: 860.6 | I6: 579363 | J6: 549015 | K6: 5.22 | L6: Banking
A7: ABBOTINDIA | B7: Tata Consultancy | C7: 25420 | D7: 26482.6 | E7: 28370.31 | F7: 36491.76 | G7: 28490 | H7: 25385 | I7: 9729 | J7: 7695 | K7: -8.82 | L7: IT
A8: GODIGIT | B8: ICICI Bank | C8: 321.7 | D8: 326.88 | E8: 334.6 | F8: 381.4 | G8: 350 | H8: 311.85 | I8: 187919 | J8: 226046 | K8: -5.09 | L8: Banking
A9: LUPIN | B9: Wipro | C9: 2307.9 | D9: 2277.28 | E9: 2143.65 | F9: 2377.6 | G9: 2377.6 | H9: 2129.4 | I9: 999957 | J9: 932836 | K9: 5.1 | L9: IT
A10: DIVISLAB | B10: Tata Motors | C10: 6285.5 | D10: 6158.66 | E10: 6247.17 | F10: 7039.45 | G10: 6793 | H10: 5821 | I10: 251355 | J10: 300339 | K10: -1.1 | L10: Auto
A11: LALPATHLAB | B11: Axis Bank | C11: 1459.1 | D11: 1389.79 | E11: 1441.86 | F11: 1761.62 | G11: 1474 | H11: 1307.6 | I11: 337894 | J11: 257866 | K11: 3.73 | L11: Banking
A12: NHPC | B12: Sun Pharma | C12: 82.63 | D12: 77.49 | E12: 79.15 | F12: 90.16 | G12: 85.78 | H12: 72.23 | I12: 14949031 | J12: 14584257 | K12: 3.48 | L12: Pharma
A13: GICRE | B13: Bajaj Finance | C13: 399.3 | D13: 380.86 | E13: 381.47 | F13: 441.62 | G13: 417.95 | H13: 357.3 | I13: 523504 | J13: 404087 | K13: 9.55 | L13: NBFC
A14: AADHARHFC | C14: 489.5 | D14: 472.25 | E14: 479.56 | F14: 547.8 | G14: 506.7 | H14: 439.1 | I14: 340024 | J14: 346480 | K14: 2.51
A15: HSCL | C15: 523.1 | D15: 467.08 | E15: 464.1 | F15: 534.45 | G15: 525.25 | H15: 438.15 | I15: 3174290 | J15: 1921374 | K15: 11.22
A16: RELIANCE | C16: 1362.1 | D16: 1386.45 | E16: 1423.88 | F16: 1611.8 | G16: 1489.5 | H16: 1304.6 | I16: 20725390 | J16: 17167161 | K16: -6.63
A17: MARICO | C17: 772.5 | D17: 757 | E17: 740.47 | F17: 813.5 | G17: 813.5 | H17: 722.4 | I17: 1973962 | J17: 1755248 | K17: 3.03
A18: STARCEMENT | C18: 229.92 | D18: 214.79 | E18: 224.57 | F18: 307.54 | G18: 242.33 | H18: 198.17 | I18: 193193 | J18: 220219 | K18: 7.77
A19: CANHLIFE
A20: PIRAMALFIN
A21: JLHL | C21: 1292.2 | D21: 1275.28 | E21: 1366.71 | F21: 1625 | G21: 1399 | H21: 1199.9 | I21: 15540 | J21: 16006 | K21: -4.62
A22: ANURAS | C22: 1343.3 | D22: 1271.21 | E22: 1190.17 | F22: 1407 | G22: 1407 | H22: 1217 | I22: 190053 | J22: 193251 | K22: 1.67
A23: STARHEALTH | C23: 508.8 | D23: 469.83 | E23: 456.6 | F23: 534 | G23: 518.4 | H23: 425.15 | I23: 474897 | J23: 358056 | K23: 14.3
A24: CHAMBLFERT | C24: 452.3 | D24: 444.97 | E24: 486.29 | F24: 727.39 | G24: 473.8 | H24: 412.25 | I24: 678735 | J24: 774492 | K24: 1.39
A25: TORNTPHARM | C25: 4084.6 | D25: 4151.44 | E25: 3852.39 | F25: 4482.9 | G25: 4482.9 | H25: 3903.34 | I25: 362204 | J25: 354702 | K25: 2.72
A26: BRITANNIA | C26: 5729.5 | D26: 5753.29 | E26: 5789.03 | F26: 6336 | G26: 6208.5 | H26: 5423 | I26: 378825 | J26: 339513 | K26: -3
A27: NESTLEIND | C27: 1395.8 | D27: 1254.68 | E27: 1238.27 | F27: 1425.2 | G27: 1425.2 | H27: 1166.8 | I27: 1358310 | J27: 1144239 | K27: 7.36
A28: IRB | C28: 22.15 | D28: 21.15 | E28: 21.61 | F28: 27.01 | G28: 22.7 | H28: 19.46 | I28: 15070334 | J28: 14703716 | K28: 6.18
A29: USHAMART | C29: 444.95 | D29: 422.54 | E29: 406.37 | F29: 497.1 | G29: 454.65 | H29: 387.35 | I29: 286558 | J29: 335650 | K29: 2.46
A30: IPCALAB | C30: 1494.8 | D30: 1489.03 | E30: 1443.48 | F30: 1624 | G30: 1624 | H30: 1406.4 | I30: 196016 | J30: 178953 | K30: -0.86
A31: BHARTIARTL | C31: 1829 | D31: 1882.83 | E31: 1937.84 | F31: 2174.5 | G31: 2057 | H31: 1781.9 | I31: 10113053 | J31: 8073518 | K31: -9.57
A32: DRREDDY | C32: 1217 | D32: 1250.14 | E32: 1248.96 | F32: 1371 | G32: 1337.3 | H32: 1157.2 | I32: 2063229 | J32: 1672460 | K32: 2.57
... A34: NAVINFLUOR | C34: 6267 | D34: 6181.19 | E34: 5669.17 | F34: 6965 | G34: 6965 | H34: 5801.5 | I34: 148585 | J34: 156288 | K34: 4.66
A35: JSWDULUX
A36: SUNPHARMA | C36: 1669.8 | D36: 1720.92 | E36: 1716.54 | F36: 1843 | G36: 1843 | H36: 1579.04 | I36: 3276165 | J36: 2783613 | K36: -1.18
A37: BAYERCROP | C37: 4787.9 | D37: 4678.53 | E37: 4757.32 | F37: 6344.3 | G37: 5063 | H37: 4355.3 | I37: 20650 | J37: 18801 | K37: 8.51
A38: APOLLOHOSP | C38: 7662 | D38: 7483.6 | E38: 7376.5 | F38: 8088.76 | G38: 7870.5 | H38: 6784.49 | I38: 416753 | J38: 431623 | K38: 5.5
A39: PFIZER | C39: 4764.1 | D39: 4835.82 | E39: 4891.25 | F39: 5873.5 | G39: 5257 | H39: 4551 | I39: 14382 | J39: 12221 | K39: -1.15
A40: COALINDIA | C40: 444.15 | D40: 438.42 | E40: 405.83 | F40: 476 | G40: 476 | H40: 403.61 | I40: 11316785 | J40: 9618062 | K40: 4.12
A41: THELEELA | C41: 432.55 | D41: 425.15 | E41: 426.35 | F41: 474.4 | G41: 471 | H41: 393.75 | I41: 173548 | J41: 202434 | K41: -1.6
...

Sheet Screener & Ranking
A1: 🎯 SCREENER & RANKING ENGINE — Monday 3 PM Entry Signals
A2: All filters auto-calculated from Ticker Data sheet. Green = PASS | Red = FAIL | Top 20 by Composite Score highlighted in gold.
A3: IDENTIFIER | D3: FILTER CHECKS | H3: RANKING FACTORS | M3: RANK SCORES (0–100) | Q3: COMPOSITE | S3: DECISION
A4: Ticker | B4: Company | C4: Sector | D4: Price> 50EMA> 200EMA | E4: Price <15% from 52W High | F4: 3M Breakout? | G4: Vol Surge 1M>3M? | H4: 3M Return % | I4: Vol Surge Ratio | J4: Breakout Strength % | K4: EMA Sep % | L4: 52W High Prox % | M4: Momentum Score | N4: Volume Score | O4: Breakout Score | P4: EMA Score | Q4: Composite Score | R4: Rank | S4: All Filters Pass? | T4: Top 20 Signal
A5: =IF('Ticker Data'!A4="","",'Ticker Data'!A4) | B5: =IF('Ticker Data'!A4="","",'Ticker Data'!B4) | C5: =IF('Ticker Data'!A4="","",'Ticker Data'!L4) | D5: =IF('Ticker Data'!A4="","",IF(AND('Ticker Data'!C4>'Ticker Data'!D4,'Ticker Data'!D4>'Ticker Data'!E4,'Ticker Data'!E4>0),"✔ PASS","✘ FAIL")) | E5: =IF('Ticker Data'!A4="","",IF('Ticker Data'!C4>='Ticker Data'!F4*0.85,"✔ PASS","✘ FAIL")) | F5: =IF('Ticker Data'!A4="","",IF('Ticker Data'!C4>='Ticker Data'!G4,"✔ PASS","✘ FAIL")) | G5: =IF('Ticker Data'!A4="","",IF('Ticker Data'!I4>'Ticker Data'!J4,"✔ PASS","✘ FAIL")) | H5: =IF('Ticker Data'!A4="","",(('Ticker Data'!K4/100))) | I5: =IF(OR('Ticker Data'!A4="",'Ticker Data'!J4=0),"",'Ticker Data'!I4/'Ticker Data'!J4) | J5: =IF(OR('Ticker Data'!A4="",'Ticker Data'!G4=0),"",('Ticker Data'!C4-'Ticker Data'!G4)/'Ticker Data'!G4) | K5: =IF(OR('Ticker Data'!A4="",'Ticker Data'!D4=0),"",('Ticker Data'!C4-'Ticker Data'!D4)/'Ticker Data'!D4) | L5: =IF(OR('Ticker Data'!A4="",'Ticker Data'!F4=0),"",'Ticker Data'!C4/'Ticker Data'!F4) | M5: =IF(OR(C5="",H5=""),"",ROUND(PERCENTRANK($H$5:$H$54,H5)*100,1)) | N5: =IF(OR(C5="",I5=""),"",ROUND(PERCENTRANK($I$5:$I$54,I5)*100,1)) | O5: =IF(OR(C5="",J5=""),"",ROUND(PERCENTRANK($J$5:$J$54,J5)*100,1)) | P5: =IF(OR(C5="",K5=""),"",ROUND(PERCENTRANK($K$5:$K$54,K5)*100,1)) | Q5: =IF(OR(A5="",D5=""),"",ROUND(M5*0.3+N5*0.25+O5*0.25+P5*0.2,1)) | R5: =IF(OR(A5="",S5<>"✔ ALL PASS"),"",RANK(Q5,$Q$5:$Q$54,0)) | S5: =IF(A5="","",IF(AND(D5="✔ PASS",E5="✔ PASS",F5="✔ PASS",G5="✔ PASS"),"✔ ALL PASS","✘ FILTERED")) | T5: =IF(OR(A5="",S5<>"✔ ALL PASS",R5=""),"",IF(R5<=20,"🟢 BUY SIGNAL","—"))
A6: =IF('Ticker Data'!A5="","",'Ticker Data'!A5) | B6: =IF('Ticker Data'!A5="","",'Ticker Data'!B5) | C6: =IF('Ticker Data'!A5="","",'Ticker Data'!L5) | D6: =IF('Ticker Data'!A5="","",IF(AND('Ticker Data'!C5>'Ticker Data'!D5,'Ticker Data'!D5>'Ticker Data'!E5,'Ticker Data'!E5>0),"✔ PASS","✘ FAIL")) | E6: =IF('Ticker Data'!A5="","",IF('Ticker Data'!C5>='Ticker Data'!F5*0.85,"✔ PASS","✘ FAIL")) | F6: =IF('Ticker Data'!A5="","",IF('Ticker Data'!C5>='Ticker Data'!G5,"✔ PASS","✘ FAIL")) | G6: =IF('Ticker Data'!A5="","",IF('Ticker Data'!I5>'Ticker Data'!J5,"✔ PASS","✘ FAIL")) | H6: =IF('Ticker Data'!A5="","",(('Ticker Data'!K5/100))) | I6: =IF(OR('Ticker Data'!A5="",'Ticker Data'!J5=0),"",'Ticker Data'!I5/'Ticker Data'!J5) | J6: =IF(OR('Ticker Data'!A5="",'Ticker Data'!G5=0),"",('Ticker Data'!C5-'Ticker Data'!G5)/'Ticker Data'!G5) | K6: =IF(OR('Ticker Data'!A5="",'Ticker Data'!D5=0),"",('Ticker Data'!C5-'Ticker Data'!D5)/'Ticker Data'!D5) | L6: =IF(OR('Ticker Data'!A5="",'Ticker Data'!F5=0),"",'Ticker Data'!C5/'Ticker Data'!F5) | M6: =IF(OR(C6="",H6=""),"",ROUND(PERCENTRANK($H$5:$H$54,H6)*100,1)) | N6: =IF(OR(C6="",I6=""),"",ROUND(PERCENTRANK($I$5:$I$54,I6)*100,1)) | O6: =IF(OR(C6="",J6=""),"",ROUND(PERCENTRANK($J$5:$J$54,J6)*100,1)) | P6: =IF(OR(C6="",K6=""),"",ROUND(PERCENTRANK($K$5:$K$54,K6)*100,1)) | Q6: =IF(OR(A6="",D6=""),"",ROUND(M6*0.3+N6*0.25+O6*0.25+P6*0.2,1)) | R6: =IF(OR(A6="",S6<>"✔ ALL PASS"),"",RANK(Q6,$Q$5:$Q$54,0)) | S6: =IF(A6="","",IF(AND(D6="✔ PASS",E6="✔ PASS",F6="✔ PASS",G6="✔ PASS"),"✔ ALL PASS","✘ FILTERED")) | T6: =IF(OR(A6="",S6<>"✔ ALL PASS",R6=""),"",IF(R6<=20,"🟢 BUY SIGNAL","—"))
A7: =IF('Ticker Data'!A6="","",'Ticker Data'!A6) | B7: =IF('Ticker Data'!A6="","",'Ticker Data'!B6) | C7: =IF('Ticker Data'!A6="","",'Ticker Data'!L6) | D7: =IF('Ticker Data'!A6="","",IF(AND('Ticker Data'!C6>'Ticker Data'!D6,'Ticker Data'!D6>'Ticker Data'!E6,'Ticker Data'!E6>0),"✔ PASS","✘ FAIL")) | E7: =IF('Ticker Data'!A6="","",IF('Ticker Data'!C6>='Ticker Data'!F6*0.85,"✔ PASS","✘ FAIL")) | F7: =IF('Ticker Data'!A6="","",IF('Ticker Data'!C6>='Ticker Data'!G6,"✔ PASS","✘ FAIL")) | G7: =IF('Ticker Data'!A6="","",IF('Ticker Data'!I6>'Ticker Data'!J6,"✔ PASS","✘ FAIL")) | H7: =IF('Ticker Data'!A6="","",(('Ticker Data'!K6/100))) | I7: =IF(OR('Ticker Data'!A6="",'Ticker Data'!J6=0),"",'Ticker Data'!I6/'Ticker Data'!J6) | J7: =IF(OR('Ticker Data'!A6="",'Ticker Data'!G6=0),"",('Ticker Data'!C6-'Ticker Data'!G6)/'Ticker Data'!G6) | K7: =IF(OR('Ticker Data'!A6="",'Ticker Data'!D6=0),"",('Ticker Data'!C6-'Ticker Data'!D6)/'Ticker Data'!D6) | L7: =IF(OR('Ticker Data'!A6="",'Ticker Data'!F6=0),"",'Ticker Data'!C6/'Ticker Data'!F6) | M7: =IF(OR(C7="",H7=""),"",ROUND(PERCENTRANK($H$5:$H$54,H7)*100,1)) | N7: =IF(OR(C7="",I7=""),"",ROUND(PERCENTRANK($I$5:$I$54,I7)*100,1)) | O7: =IF(OR(C7="",J7=""),"",ROUND(PERCENTRANK($J$5:$J$54,J7)*100,1)) | P7: =IF(OR(C7="",K7=""),"",ROUND(PERCENTRANK($K$5:$K$54,K7)*100,1)) | Q7: =IF(OR(A7="",D7=""),"",ROUND(M7*0.3+N7*0.25+O7*0.25+P7*0.2,1)) | R7: =IF(OR(A7="",S7<>"✔ ALL PASS"),"",RANK(Q7,$Q$5:$Q$54,0)) | S7: =IF(A7="","",IF(AND(D7="✔ PASS",E7="✔ PASS",F7="✔ PASS",G7="✔ PASS"),"✔ ALL PASS","✘ FILTERED")) | T7: =IF(OR(A7="",S7<>"✔ ALL PASS",R7=""),"",IF(R7<=20,"🟢 BUY SIGNAL","—"))
A8: =IF('Ticker Data'!A7="","",'Ticker Data'!A7) | B8: =IF('Ticker Data'!A7="","",'Ticker Data'!B7) | C8: =IF('Ticker Data'!A7="","",'Ticker Data'!L7) | D8: =IF('Ticker Data'!A7="","",IF(AND('Ticker Data'!C7>'Ticker Data'!D7,'Ticker Data'!D7>'Ticker Data'!E7,'Ticker Data'!E7>0),"✔ PASS","✘ FAIL")) | E8: =IF('Ticker Data'!A7="","",IF('Ticker Data'!C7>='Ticker Data'!F7*0.85,"✔ PASS","✘ FAIL")) | F8: =IF('Ticker Data'!A7="","",IF('Ticker Data'!C7>='Ticker Data'!G7,"✔ PASS","✘ FAIL")) | G8: =IF('Ticker Data'!A7="","",IF('Ticker Data'!I7>'Ticker Data'!J7,"✔ PASS","✘ FAIL")) | H8: =IF('Ticker Data'!A7="","",(('Ticker Data'!K7/100))) | I8: =IF(OR('Ticker Data'!A7="",'Ticker Data'!J7=0),"",'Ticker Data'!I7/'Ticker Data'!J7) | J8: =IF(OR('Ticker Data'!A7="",'Ticker Data'!G7=0),"",('Ticker Data'!C7-'Ticker Data'!G7)/'Ticker Data'!G7) | K8: =IF(OR('Ticker Data'!A7="",'Ticker Data'!D7=0),"",('Ticker Data'!C7-'Ticker Data'!D7)/'Ticker Data'!D7) | L8: =IF(OR('Ticker Data'!A7="",'Ticker Data'!F7=0),"",'Ticker Data'!C7/'Ticker Data'!F7) | M8: =IF(OR(C8="",H8=""),"",ROUND(PERCENTRANK($H$5:$H$54,H8)*100,1)) | N8: =IF(OR(C8="",I8=""),"",ROUND(PERCENTRANK($I$5:$I$54,I8)*100,1)) | O8: =IF(OR(C8="",J8=""),"",ROUND(PERCENTRANK($J$5:$J$54,J8)*100,1)) | P8: =IF(OR(C8="",K8=""),"",ROUND(PERCENTRANK($K$5:$K$54,K8)*100,1)) | Q8: =IF(OR(A8="",D8=""),"",ROUND(M8*0.3+N8*0.25+O8*0.25+P8*0.2,1)) | R8: =IF(OR(A8="",S8<>"✔ ALL PASS"),"",RANK(Q8,$Q$5:$Q$54,0)) | S8: =IF(A8="","",IF(AND(D8="✔ PASS",E8="✔ PASS",F8="✔ PASS",G8="✔ PASS"),"✔ ALL PASS","✘ FILTERED")) | T8: =IF(OR(A8="",S8<>"✔ ALL PASS",R8=""),"",IF(R8<=20,"🟢 BUY SIGNAL","—"))
A9: =IF('Ticker Data'!A8="","",'Ticker Data'!A8) | B9: =IF('Ticker Data'!A8="","",'Ticker Data'!B8) | C9: =IF('Ticker Data'!A8="","",'Ticker Data'!L8) | D9: =IF('Ticker Data'!A8="","",IF(AND('Ticker Data'!C8>'Ticker Data'!D8,'Ticker Data'!D8>'Ticker Data'!E8,'Ticker Data'!E8>0),"✔ PASS","✘ FAIL")) | E9: =IF('Ticker Data'!A8="","",IF('Ticker Data'!C8>='Ticker Data'!F8*0.85,"✔ PASS","✘ FAIL")) | F9: =IF('Ticker Data'!A8="","",IF('Ticker Data'!C8>='Ticker Data'!G8,"✔ PASS","✘ FAIL")) | G9: =IF('Ticker Data'!A8="","",IF('Ticker Data'!I8>'Ticker Data'!J8,"✔ PASS","✘ FAIL")) | H9: =IF('Ticker Data'!A8="","",(('Ticker Data'!K8/100))) | I9: =IF(OR('Ticker Data'!A8="",'Ticker Data'!J8=0),"",'Ticker Data'!I8/'Ticker Data'!J8) | J9: =IF(OR('Ticker Data'!A8="",'Ticker Data'!G8=0),"",('Ticker Data'!C8-'Ticker Data'!G8)/'Ticker Data'!G8) | K9: =IF(OR('Ticker Data'!A8="",'Ticker Data'!D8=0),"",('Ticker Data'!C8-'Ticker Data'!D8)/'Ticker Data'!D8) | L9: =IF(OR('Ticker Data'!A8="",'Ticker Data'!F8=0),"",'Ticker Data'!C8/'Ticker Data'!F8) | M9: =IF(OR(C9="",H9=""),"",ROUND(PERCENTRANK($H$5:$H$54,H9)*100,1)) | N9: =IF(OR(C9="",I9=""),"",ROUND(PERCENTRANK($I$5:$I$54,I9)*100,1)) | O9: =IF(OR(C9="",J9=""),"",ROUND(PERCENTRANK($J$5:$J$54,J9)*100,1)) | P9: =IF(OR(C9="",K9=""),"",ROUND(PERCENTRANK($K$5:$K$54,K9)*100,1)) | Q9: =IF(OR(A9="",D9=""),"",ROUND(M9*0.3+N9*0.25+O9*0.25+P9*0.2,1)) | R9: =IF(OR(A9="",S9<>"✔ ALL PASS"),"",RANK(Q9,$Q$5:$Q$54,0)) | S9: =IF(A9="","",IF(AND(D9="✔ PASS",E9="✔ PASS",F9="✔ PASS",G9="✔ PASS"),"✔ ALL PASS","✘ FILTERED")) | T9: =IF(OR(A9="",S9<>"✔ ALL PASS",R9=""),"",IF(R9<=20,"🟢 BUY SIGNAL","—"))
A10: =IF('Ticker Data'!A9="","",'Ticker Data'!A9) | B10: =IF('Ticker Data'!A9="","",'Ticker Data'!B9) | C10: =IF('Ticker Data'!A9="","",'Ticker Data'!L9) | D10: =IF('Ticker Data'!A9="","",IF(AND('Ticker Data'!C9>'Ticker Data'!D9,'Ticker Data'!D9>'Ticker Data'!E9,'Ticker Data'!E9>0),"✔ PASS","✘ FAIL")) | E10: =IF('Ticker Data'!A9="","",IF('Ticker Data'!C9>='Ticker Data'!F9*0.85,"✔ PASS","✘ FAIL")) | F10: =IF('Ticker Data'!A9="","",IF('Ticker Data'!C9>='Ticker Data'!G9,"✔ PASS","✘ FAIL")) | G10: =IF('Ticker Data'!A9="","",IF('Ticker Data'!I9>'Ticker Data'!J9,"✔ PASS","✘ FAIL")) | H10: =IF('Ticker Data'!A9="","",(('Ticker Data'!K9/100))) | I10: =IF(OR('Ticker Data'!A9="",'Ticker Data'!J9=0),"",'Ticker Data'!I9/'Ticker Data'!J9) | J10: =IF(OR('Ticker Data'!A9="",'Ticker Data'!G9=0),"",('Ticker Data'!C9-'Ticker Data'!G9)/'Ticker Data'!G9) | K10: =IF(OR('Ticker Data'!A9="",'Ticker Data'!D9=0),"",('Ticker Data'!C9-'Ticker Data'!D9)/'Ticker Data'!D9) | L10: =IF(OR('Ticker Data'!A9="",'Ticker Data'!F9=0),"",'Ticker Data'!C9/'Ticker Data'!F9) | M10: =IF(OR(C10="",H10=""),"",ROUND(PERCENTRANK($H$5:$H$54,H10)*100,1)) | N10: =IF(OR(C10="",I10=""),"",ROUND(PERCENTRANK($I$5:$I$54,I10)*100,1)) | O10: =IF(OR(C10="",J10=""),"",ROUND(PERCENTRANK($J$5:$J$54,J10)*100,1)) | P10: =IF(OR(C10="",K10=""),"",ROUND(PERCENTRANK($K$5:$K$54,K10)*100,1)) | Q10: =IF(OR(A10="",D10=""),"",ROUND(M10*0.3+N10*0.25+O10*0.25+P10*0.2,1)) | R10: =IF(OR(A10="",S10<>"✔ ALL PASS"),"",RANK(Q10,$Q$5:$Q$54,0)) | S10: =IF(A10="","",IF(AND(D10="✔ PASS",E10="✔ PASS",F10="✔ PASS",G10="✔ PASS"),"✔ ALL PASS","✘ FILTERED")) | T10: =IF(OR(A10="",S10<>"✔ ALL PASS",R10=""),"",IF(R10<=20,"🟢 BUY SIGNAL","—"))
A11: =IF('Ticker Data'!A10="","",'Ticker Data'!A10) | B11: =IF('Ticker Data'!A10="","",'Ticker Data'!B10) | C11: =IF('Ticker Data'!A10="","",'Ticker Data'!L10) | D11: =IF('Ticker Data'!A10="","",IF(AND('Ticker Data'!C10>'Ticker Data'!D10,'Ticker Data'!D10>'Ticker Data'!E10,'Ticker Data'!E10>0),"✔ PASS","✘ FAIL")) | E11: =IF('Ticker Data'!A10="","",IF('Ticker Data'!C10>='Ticker Data'!F10*0.85,"✔ PASS","✘ FAIL")) | F11: =IF('Ticker Data'!A10="","",IF('Ticker Data'!C10>='Ticker Data'!G10,"✔ PASS","✘ FAIL")) | G11: =IF('Ticker Data'!A10="","",IF('Ticker Data'!I10>'Ticker Data'!J10,"✔ PASS","✘ FAIL")) | H11: =IF('Ticker Data'!A10="","",(('Ticker Data'!K10/100))) | I11: =IF(OR('Ticker Data'!A10="",'Ticker Data'!J10=0),"",'Ticker Data'!I10/'Ticker Data'!J10) | J11: =IF(OR('Ticker Data'!A10="",'Ticker Data'!G10=0),"",('Ticker Data'!C10-'Ticker Data'!G10)/'Ticker Data'!G10) | K11: =IF(OR('Ticker Data'!A10="",'Ticker Data'!D10=0),"",('Ticker Data'!C10-'Ticker Data'!D10)/'Ticker Data'!D10) | L11: =IF(OR('Ticker Data'!A10="",'Ticker Data'!F10=0),"",'Ticker Data'!C10/'Ticker Data'!F10) | M11: =IF(OR(C11="",H11=""),"",ROUND(PERCENTRANK($H$5:$H$54,H11)*100,1)) | N11: =IF(OR(C11="",I11=""),"",ROUND(PERCENTRANK($I$5:$I$54,I11)*100,1)) | O11: =IF(OR(C11="",J11=""),"",ROUND(PERCENTRANK($J$5:$J$54,J11)*100,1)) | P11: =IF(OR(C11="",K11=""),"",ROUND(PERCENTRANK($K$5:$K$54,K11)*100,1)) | Q11: =IF(OR(A11="",D11=""),"",ROUND(M11*0.3+N11*0.25+O11*0.25+P11*0.2,1)) | R11: =IF(OR(A11="",S11<>"✔ ALL PASS"),"",RANK(Q11,$Q$5:$Q$54,0)) | S11: =IF(A11="","",IF(AND(D11="✔ PASS",E11="✔ PASS",F11="✔ PASS",G11="✔ PASS"),"✔ ALL PASS","✘ FILTERED")) | T11: =IF(OR(A11="",S11<>"✔ ALL PASS",R11=""),"",IF(R11<=20,"🟢 BUY SIGNAL","—"))
A12: =IF('Ticker Data'!A11="","",'Ticker Data'!A11) | B12: =IF('Ticker Data'!A11="","",'Ticker Data'!B11) | C12: =IF('Ticker Data'!A11="","",'Ticker Data'!L11) | D12: =IF('Ticker Data'!A11="","",IF(AND('Ticker Data'!C11>'Ticker Data'!D11,'Ticker Data'!D11>'Ticker Data'!E11,'Ticker Data'!E11>0),"✔ PASS","✘ FAIL")) | E12: =IF('Ticker Data'!A11="","",IF('Ticker Data'!C11>='Ticker Data'!F11*0.85,"✔ PASS","✘ FAIL")) | F12: =IF('Ticker Data'!A11="","",IF('Ticker Data'!C11>='Ticker Data'!G11,"✔ PASS","✘ FAIL")) | G12: =IF('Ticker Data'!A11="","",IF('Ticker Data'!I11>'Ticker Data'!J11,"✔ PASS","✘ FAIL")) | H12: =IF('Ticker Data'!A11="","",(('Ticker Data'!K11/100))) | I12: =IF(OR('Ticker Data'!A11="",'Ticker Data'!J11=0),"",'Ticker Data'!I11/'Ticker Data'!J11) | J12: =IF(OR('Ticker Data'!A11="",'Ticker Data'!G11=0),"",('Ticker Data'!C11-'Ticker Data'!G11)/'Ticker Data'!G11) | K12: =IF(OR('Ticker Data'!A11="",'Ticker Data'!D11=0),"",('Ticker Data'!C11-'Ticker Data'!D11)/'Ticker Data'!D11) | L12: =IF(OR('Ticker Data'!A11="",'Ticker Data'!F11=0),"",'Ticker Data'!C11/'Ticker Data'!F11) | M12: =IF(OR(C12="",H12=""),"",ROUND(PERCENTRANK($H$5:$H$54,H12)*100,1)) | N12: =IF(OR(C12="",I12=""),"",ROUND(PERCENTRANK($I$5:$I$54,I12)*100,1)) | O12: =IF(OR(C12="",J12=""),"",ROUND(PERCENTRANK($J$5:$J$54,J12)*100,1)) | P12: =IF(OR(C12="",K12=""),"",ROUND(PERCENTRANK($K$5:$K$54,K12)*100,1)) | Q12: =IF(OR(A12="",D12=""),"",ROUND(M12*0.3+N12*0.25+O12*0.25+P12*0.2,1)) | R12: =IF(OR(A12="",S12<>"✔ ALL PASS"),"",RANK(Q12,$Q$5:$Q$54,0)) | S12: =IF(A12="","",IF(AND(D12="✔ PASS",E12="✔ PASS",F12="✔ PASS",G12="✔ PASS"),"✔ ALL PASS","✘ FILTERED")) | T12: =IF(OR(A12="",S12<>"✔ ALL PASS",R12=""),"",IF(R12<=20,"🟢 BUY SIGNAL","—"))
A13: =IF('Ticker Data'!A12="","",'Ticker Data'!A12) | B13: =IF('Ticker Data'!A12="","",'Ticker Data'!B12) | C13: =IF('Ticker Data'!A12="","",'Ticker Data'!L12) | D13: =IF('Ticker Data'!A12="","",IF(AND('Ticker Data'!C12>'Ticker Data'!D12,'Ticker Data'!D12>'Ticker Data'!E12,'Ticker Data'!E12>0),"✔ PASS","✘ FAIL")) | E13: =IF('Ticker Data'!A12="","",IF('Ticker Data'!C12>='Ticker Data'!F12*0.85,"✔ PASS","✘ FAIL")) | F13: =IF('Ticker Data'!A12="","",IF('Ticker Data'!C12>='Ticker Data'!G12,"✔ PASS","✘ FAIL")) | G13: =IF('Ticker Data'!A12="","",IF('Ticker Data'!I12>'Ticker Data'!J12,"✔ PASS","✘ FAIL")) | H13: =IF('Ticker Data'!A12="","",(('Ticker Data'!K12/100))) | I13: =IF(OR('Ticker Data'!A12="",'Ticker Data'!J12=0),"",'Ticker Data'!I12/'Ticker Data'!J12) | J13: =IF(OR('Ticker Data'!A12="",'Ticker Data'!G12=0),"",('Ticker Data'!C12-'Ticker Data'!G12)/'Ticker Data'!G12) | K13: =IF(OR('Ticker Data'!A12="",'Ticker Data'!D12=0),"",('Ticker Data'!C12-'Ticker Data'!D12)/'Ticker Data'!D12) | L13: =IF(OR('Ticker Data'!A12="",'Ticker Data'!F12=0),"",'Ticker Data'!C12/'Ticker Data'!F12) | M13: =IF(OR(C13="",H13=""),"",ROUND(PERCENTRANK($H$5:$H$54,H13)*100,1)) | N13: =IF(OR(C13="",I13=""),"",ROUND(PERCENTRANK($I$5:$I$54,I13)*100,1)) | O13: =IF(OR(C13="",J13=""),"",ROUND(PERCENTRANK($J$5:$J$54,J13)*100,1)) | P13: =IF(OR(C13="",K13=""),"",ROUND(PERCENTRANK($K$5:$K$54,K13)*100,1)) | Q13: =IF(OR(A13="",D13=""),"",ROUND(M13*0.3+N13*0.25+O13*0.25+P13*0.2,1)) | R13: =IF(OR(A13="",S13<>"✔ ALL PASS"),"",RANK(Q13,$Q$5:$Q$54,0)) | S13: =IF(A13="","",IF(AND(D13="✔ PASS",E13="✔ PASS",F13="✔ PASS",G13="✔ PASS"),"✔ ALL PASS","✘ FILTERED")) | T13: =IF(OR(A13="",S13<>"✔ ALL PASS",R13=""),"",IF(R13<=20,"🟢 BUY SIGNAL","—"))
A14: =IF('Ticker Data'!A13="","",'Ticker Data'!A13) | B14: =IF('Ticker Data'!A13="","",'Ticker Data'!B13) | C14: =IF('Ticker Data'!A13="","",'Ticker Data'!L13) | D14: =IF('Ticker Data'!A13="","",IF(AND('Ticker Data'!C13>'Ticker Data'!D13,'Ticker Data'!D13>'Ticker Data'!E13,'Ticker Data'!E13>0),"✔ PASS","✘ FAIL")) | E14: =IF('Ticker Data'!A13="","",IF('Ticker Data'!C13>='Ticker Data'!F13*0.85,"✔ PASS","✘ FAIL")) | F14: =IF('Ticker Data'!A13="","",IF('Ticker Data'!C13>='Ticker Data'!G13,"✔ PASS","✘ FAIL")) | G14: =IF('Ticker Data'!A13="","",IF('Ticker Data'!I13>'Ticker Data'!J13,"✔ PASS","✘ FAIL")) | H14: =IF('Ticker Data'!A13="","",(('Ticker Data'!K13/100))) | I14: =IF(OR('Ticker Data'!A13="",'Ticker Data'!J13=0),"",'Ticker Data'!I13/'Ticker Data'!J13) | J14: =IF(OR('Ticker Data'!A13="",'Ticker Data'!G13=0),"",('Ticker Data'!C13-'Ticker Data'!G13)/'Ticker Data'!G13) | K14: =IF(OR('Ticker Data'!A13="",'Ticker Data'!D13=0),"",('Ticker Data'!C13-'Ticker Data'!D13)/'Ticker Data'!D13) | L14: =IF(OR('Ticker Data'!A13="",'Ticker Data'!F13=0),"",'Ticker Data'!C13/'Ticker Data'!F13) | M14: =IF(OR(C14="",H14=""),"",ROUND(PERCENTRANK($H$5:$H$54,H14)*100,1)) | N14: =IF(OR(C14="",I14=""),"",ROUND(PERCENTRANK($I$5:$I$54,I14)*100,1)) | O14: =IF(OR(C14="",J14=""),"",ROUND(PERCENTRANK($J$5:$J$54,J14)*100,1)) | P14: =IF(OR(C14="",K14=""),"",ROUND(PERCENTRANK($K$5:$K$54,K14)*100,1)) | Q14: =IF(OR(A14="",D14=""),"",ROUND(M14*0.3+N14*0.25+O14*0.25+P14*0.2,1)) | R14: =IF(OR(A14="",S14<>"✔ ALL PASS"),"",RANK(Q14,$Q$5:$Q$54,0)) | S14: =IF(A14="","",IF(AND(D14="✔ PASS",E14="✔ PASS",F14="✔ PASS",G14="✔ PASS"),"✔ ALL PASS","✘ FILTERED")) | T14: =IF(OR(A14="",S14<>"✔ ALL PASS",R14=""),"",IF(R14<=20,"🟢 BUY SIGNAL","—"))
A15: =IF('Ticker Data'!A14="","",'Ticker Data'!A14) | B15: =IF('Ticker Data'!A14="","",'Ticker Data'!B14) | C15: =IF('Ticker Data'!A14="","",'Ticker Data'!L14) | D15: =IF('Ticker Data'!A14="","",IF(AND('Ticker Data'!C14>'Ticker Data'!D14,'Ticker Data'!D14>'Ticker Data'!E14,'Ticker Data'!E14>0),"✔ PASS","✘ FAIL")) | E15: =IF('Ticker Data'!A14="","",IF('Ticker Data'!C14>='Ticker Data'!F14*0.85,"✔ PASS","✘ FAIL")) | F15: =IF('Ticker Data'!A14="","",IF('Ticker Data'!C14>='Ticker Data'!G14,"✔ PASS","✘ FAIL")) | G15: =IF('Ticker Data'!A14="","",IF('Ticker Data'!I14>'Ticker Data'!J14,"✔ PASS","✘ FAIL")) | H15: =IF('Ticker Data'!A14="","",(('Ticker Data'!K14/100))) | I15: =IF(OR('Ticker Data'!A14="",'Ticker Data'!J14=0),"",'Ticker Data'!I14/'Ticker Data'!J14) | J15: =IF(OR('Ticker Data'!A14="",'Ticker Data'!G14=0),"",('Ticker Data'!C14-'Ticker Data'!G14)/'Ticker Data'!G14) | K15: =IF(OR('Ticker Data'!A14="",'Ticker Data'!D14=0),"",('Ticker Data'!C14-'Ticker Data'!D14)/'Ticker Data'!D14) | L15: =IF(OR('Ticker Data'!A14="",'Ticker Data'!F14=0),"",'Ticker Data'!C14/'Ticker Data'!F14) | M15: =IF(OR(C15="",H15=""),"",ROUND(PERCENTRANK($H$5:$H$54,H15)*100,1)) | N15: =IF(OR(C15="",I15=""),"",ROUND(PERCENTRANK($I$5:$I$54,I15)*100,1)) | O15: =IF(OR(C15="",J15=""),"",ROUND(PERCENTRANK($J$5:$J$54,J15)*100,1)) | P15: =IF(OR(C15="",K15=""),"",ROUND(PERCENTRANK($K$5:$K$54,K15)*100,1)) | Q15: =IF(OR(A15="",D15=""),"",ROUND(M15*0.3+N15*0.25+O15*0.25+P15*0.2,1)) | R15: =IF(OR(A15="",S15<>"✔ ALL PASS"),"",RANK(Q15,$Q$5:$Q$54,0)) | S15: =IF(A15="","",IF(AND(D15="✔ PASS",E15="✔ PASS",F15="✔ PASS",G15="✔ PASS"),"✔ ALL PASS","✘ FILTERED")) | T15: =IF(OR(A15="",S15<>"✔ ALL PASS",R15=""),"",IF(R15<=20,"🟢 BUY SIGNAL","—"))
A16: =IF('Ticker Data'!A15="","",'Ticker Data'!A15) | B16: =IF('Ticker Data'!A15="","",'Ticker Data'!B15) | C16: =IF('Ticker Data'!A15="","",'Ticker Data'!L15) | D16: =IF('Ticker Data'!A15="","",IF(AND('Ticker Data'!C15>'Ticker Data'!D15,'Ticker Data'!D15>'Ticker Data'!E15,'Ticker Data'!E15>0),"✔ PASS","✘ FAIL")) | E16: =IF('Ticker Data'!A15="","",IF('Ticker Data'!C15>='Ticker Data'!F15*0.85,"✔ PASS","✘ FAIL")) | F16: =IF('Ticker Data'!A15="","",IF('Ticker Data'!C15>='Ticker Data'!G15,"✔ PASS","✘ FAIL")) | G16: =IF('Ticker Data'!A15="","",IF('Ticker Data'!I15>'Ticker Data'!J15,"✔ PASS","✘ FAIL")) | H16: =IF('Ticker Data'!A15="","",(('Ticker Data'!K15/100))) | I16: =IF(OR('Ticker Data'!A15="",'Ticker Data'!J15=0),"",'Ticker Data'!I15/'Ticker Data'!J15) | J16: =IF(OR('Ticker Data'!A15="",'Ticker Data'!G15=0),"",('Ticker Data'!C15-'Ticker Data'!G15)/'Ticker Data'!G15) | K16: =IF(OR('Ticker Data'!A15="",'Ticker Data'!D15=0),"",('Ticker Data'!C15-'Ticker Data'!D15)/'Ticker Data'!D15) | L16: =IF(OR('Ticker Data'!A15="",'Ticker Data'!F15=0),"",'Ticker Data'!C15/'Ticker Data'!F15) | M16: =IF(OR(C16="",H16=""),"",ROUND(PERCENTRANK($H$5:$H$54,H16)*100,1)) | N16: =IF(OR(C16="",I16=""),"",ROUND(PERCENTRANK($I$5:$I$54,I16)*100,1)) | O16: =IF(OR(C16="",J16=""),"",ROUND(PERCENTRANK($J$5:$J$54,J16)*100,1)) | P16: =IF(OR(C16="",K16=""),"",ROUND(PERCENTRANK($K$5:$K$54,K16)*100,1)) | Q16: =IF(OR(A16="",D16=""),"",ROUND(M16*0.3+N16*0.25+O16*0.25+P16*0.2,1)) | R16: =IF(OR(A16="",S16<>"✔ ALL PASS"),"",RANK(Q16,$Q$5:$Q$54,0)) | S16: =IF(A16="","",IF(AND(D16="✔ PASS",E16="✔ PASS",F16="✔ PASS",G16="✔ PASS"),"✔ ALL PASS","✘ FILTERED")) | T16: =IF(OR(A16="",S16<>"✔ ALL PASS",R16=""),"",IF(R16<=20,"🟢 BUY SIGNAL","—"))
... A54: =IF('Ticker Data'!A53="","",'Ticker Data'!A53) | B54: =IF('Ticker Data'!A53="","",'Ticker Data'!B53) | C54: =IF('Ticker Data'!A53="","",'Ticker Data'!L53) | D54: =IF('Ticker Data'!A53="","",IF(AND('Ticker Data'!C53>'Ticker Data'!D53,'Ticker Data'!D53>'Ticker Data'!E53,'Ticker Data'!E53>0),"✔ PASS","✘ FAIL")) | E54: =IF('Ticker Data'!A53="","",IF('Ticker Data'!C53>='Ticker Data'!F53*0.85,"✔ PASS","✘ FAIL")) | F54: =IF('Ticker Data'!A53="","",IF('Ticker Data'!C53>='Ticker Data'!G53,"✔ PASS","✘ FAIL")) | G54: =IF('Ticker Data'!A53="","",IF('Ticker Data'!I53>'Ticker Data'!J53,"✔ PASS","✘ FAIL")) | H54: =IF('Ticker Data'!A53="","",(('Ticker Data'!K53/100))) | I54: =IF(OR('Ticker Data'!A53="",'Ticker Data'!J53=0),"",'Ticker Data'!I53/'Ticker Data'!J53) | J54: =IF(OR('Ticker Data'!A53="",'Ticker Data'!G53=0),"",('Ticker Data'!C53-'Ticker Data'!G53)/'Ticker Data'!G53) | K54: =IF(OR('Ticker Data'!A53="",'Ticker Data'!D53=0),"",('Ticker Data'!C53-'Ticker Data'!D53)/'Ticker Data'!D53) | L54: =IF(OR('Ticker Data'!A53="",'Ticker Data'!F53=0),"",'Ticker Data'!C53/'Ticker Data'!F53) | M54: =IF(OR(C54="",H54=""),"",ROUND(PERCENTRANK($H$5:$H$54,H54)*100,1)) | N54: =IF(OR(C54="",I54=""),"",ROUND(PERCENTRANK($I$5:$I$54,I54)*100,1)) | O54: =IF(OR(C54="",J54=""),"",ROUND(PERCENTRANK($J$5:$J$54,J54)*100,1)) | P54: =IF(OR(C54="",K54=""),"",ROUND(PERCENTRANK($K$5:$K$54,K54)*100,1)) | Q54: =IF(OR(A54="",D54=""),"",ROUND(M54*0.3+N54*0.25+O54*0.25+P54*0.2,1)) | R54: =IF(OR(A54="",S54<>"✔ ALL PASS"),"",RANK(Q54,$Q$5:$Q$54,0)) | S54: =IF(A54="","",IF(AND(D54="✔ PASS",E54="✔ PASS",F54="✔ PASS",G54="✔ PASS"),"✔ ALL PASS","✘ FILTERED")) | T54: =IF(OR(A54="",S54<>"✔ ALL PASS",R54=""),"",IF(R54<=20,"🟢 BUY SIGNAL","—"))

Sheet Top 20 Signals
A1: 🟢 TOP 20 BUY SIGNALS — 22 Apr 2026 15:52 | 6 Filters: Trend | 52W Prox | >=3MH | <6MH | Vol Surge | R/R≥1.5x
A2: Rank | B2: Ticker | C2: Price ₹ | D2: 3M Ret % | E2: Vol Ratio | F2: Score | G2: Risk ₹ | H2: Risk % | I2: Reward ₹ | J2: Reward % | K2: R/R Ratio | L2: 6M Headroom % | M2: TSL (−5%) | N2: Target (+10%) | O2: F1 Trend | P2: F2 52W | Q2: F3 >=3MH | R2: F4 <6MH | S2: F5 Vol | T2: F6 R/R
A24: Risk = Price × 5% (TSL) | Reward = 6M High − Price | R/R = Reward ÷ Risk | Min R/R = 1.5x | 🟢 ≥2.0x 🟡 1.5–1.99x · F1:Trend F2:52WH F3:3MBO F4:<6MH F5:VolSurge F6:R/R
